Workbook

Sheet Start Here
A1: EL Data Dashboard — Mississippi ELPT / ELPA21
A3: What it does | B3: Paste your district or school EL roster into the Students sheet; the Dashboard sheet computes counts by level, domain averages, % proficient, growth from last year, years-in-program distribution, monitored students, and a by-grade table — with charts — using formulas only. Nothing is hard-coded.
A4: How to fill it | B4: 1. Export your EL roster (MSIS or your SIS) with: student ID, school, grade, home language, years in program, this year's ELPT levels by domain, last year's overall, and status. 2. Paste rows into the Students sheet starting at row 2 — blue cells are inputs; black cells are formulas. 3. Keep the column order. Delete the example rows first. 4. Dashboard updates automatically. Up to 1,000 students; extend formulas if you have more.
A5: Columns | B5: ID · School · Grade (K, 1–12) · Home language · Years in EL program (1 = first year) · Listening · Speaking · Reading · Writing (1–5 this year) · Last year overall (1–5, blank if new) · Status (EL, Declined, Monitored Y1–Y4) · IEP (Y/N) · Notes. Overall and Proficient? are formulas.
A6: Definitions | B6: Proficient (exit) = Level 4 or 5 in ALL four domains (Mississippi ELPT exit rule). Overall label: Emerging = all domains 1–2; Progressing = anything else below proficient. Growth = this year's overall minus last year's overall. Lowest domain = the domain to target in the LSP.
A7: Privacy | B7: This file holds student-level data. Store it where your district stores FERPA-protected records; strip names before sharing charts. Example rows are fictional.
A8: Source | B8: Levels and exit rule: ELPA21 proficiency determinations as used by the Mississippi Department of Education (ELPT), 2026–27. Template by Richard A. Daniel, M.Ed., EL Publishing — radan55.github.io/everyteacher
A10: Legend: | B10: Blue text = you type it · Black = formula, leave it · Yellow = dashboard results

Sheet Dashboard
A1: EL Data Dashboard
A2: ="Active ELs (status EL or Declined): "&COUNTIFS(Students!O:O,"EL")+COUNTIFS(Students!O:O,"Declined")&" · Monitored: "&COUNTIF(Students!O:O,"Monitored*")&" · Updated "&TEXT(TODAY(),"mmm d, yyyy") -> Active ELs (status EL or Declined): 36 · Monitored: 4 · Updated Oct 3, 2026
A4: 1 · Overall determination (active ELs) | E4: 2 · Average level by domain (active ELs)
A5: Label | B5: Students | C5: % of ELs | E5: Domain | F5: Average | G5: At 4–5 | H5: % at 4–5
A6: Emerging | B6: =COUNTIFS(Students!$O:$O,"EL",Students!$J:$J,A6)+COUNTIFS(Students!$O:$O,"Declined",Students!$J:$J,A6) -> 12 | C6: =IF($B$9=0,0,B6/$B$9) -> 0.33333333 | E6: Listening | F6: =IFERROR(ROUND((SUMIFS(Students!$F:$F,Students!$O:$O,"EL")+SUMIFS(Students!$F:$F,Students!$O:$O,"Declined"))/$B$9,2),0) -> 3.39 | G6: =COUNTIFS(Students!$O:$O,"EL",Students!$F:$F,">=4")+COUNTIFS(Students!$O:$O,"Declined",Students!$F:$F,">=4") -> 18 | H6: =IF($B$9=0,0,G6/$B$9) -> 0.5
A7: Progressing | B7: =COUNTIFS(Students!$O:$O,"EL",Students!$J:$J,A7)+COUNTIFS(Students!$O:$O,"Declined",Students!$J:$J,A7) -> 13 | C7: =IF($B$9=0,0,B7/$B$9) -> 0.36111111 | E7: Speaking | F7: =IFERROR(ROUND((SUMIFS(Students!$G:$G,Students!$O:$O,"EL")+SUMIFS(Students!$G:$G,Students!$O:$O,"Declined"))/$B$9,2),0) -> 2.92 | G7: =COUNTIFS(Students!$O:$O,"EL",Students!$G:$G,">=4")+COUNTIFS(Students!$O:$O,"Declined",Students!$G:$G,">=4") -> 15 | H7: =IF($B$9=0,0,G7/$B$9) -> 0.41666667
A8: Proficient | B8: =COUNTIFS(Students!$O:$O,"EL",Students!$J:$J,A8)+COUNTIFS(Students!$O:$O,"Declined",Students!$J:$J,A8) -> 11 | C8: =IF($B$9=0,0,B8/$B$9) -> 0.30555556 | E8: Reading | F8: =IFERROR(ROUND((SUMIFS(Students!$H:$H,Students!$O:$O,"EL")+SUMIFS(Students!$H:$H,Students!$O:$O,"Declined"))/$B$9,2),0) -> 2.56 | G8: =COUNTIFS(Students!$O:$O,"EL",Students!$H:$H,">=4")+COUNTIFS(Students!$O:$O,"Declined",Students!$H:$H,">=4") -> 12 | H8: =IF($B$9=0,0,G8/$B$9) -> 0.33333333
A9: Total | B9: =SUM(B6:B8) -> 36 | C9: =IF(B9=0,0,SUM(C6:C8)) -> 1 | E9: Writing | F9: =IFERROR(ROUND((SUMIFS(Students!$I:$I,Students!$O:$O,"EL")+SUMIFS(Students!$I:$I,Students!$O:$O,"Declined"))/$B$9,2),0) -> 2.81 | G9: =COUNTIFS(Students!$O:$O,"EL",Students!$I:$I,">=4")+COUNTIFS(Students!$O:$O,"Declined",Students!$I:$I,">=4") -> 15 | H9: =IF($B$9=0,0,G9/$B$9) -> 0.41666667
A12: 3 · Students at each level, by domain | H12: 4 · Growth since last year (students with a prior score)
A13: Level | B13: Listening | C13: Speaking | D13: Reading | E13: Writing | H13: Measure | I13: Value
A14: 1 | B14: =COUNTIFS(Students!$O:$O,"EL",Students!$F:$F,$A14)+COUNTIFS(Students!$O:$O,"Declined",Students!$F:$F,$A14) -> 4 | C14: =COUNTIFS(Students!$O:$O,"EL",Students!$G:$G,$A14)+COUNTIFS(Students!$O:$O,"Declined",Students!$G:$G,$A14) -> 10 | D14: =COUNTIFS(Students!$O:$O,"EL",Students!$H:$H,$A14)+COUNTIFS(Students!$O:$O,"Declined",Students!$H:$H,$A14) -> 12 | E14: =COUNTIFS(Students!$O:$O,"EL",Students!$I:$I,$A14)+COUNTIFS(Students!$O:$O,"Declined",Students!$I:$I,$A14) -> 12 | H14: Students with prior score | I14: =COUNTIFS(Students!$O:$O,"EL",Students!$M:$M,">0")+COUNTIFS(Students!$O:$O,"Declined",Students!$M:$M,">0") -> 30
A15: 2 | B15: =COUNTIFS(Students!$O:$O,"EL",Students!$F:$F,$A15)+COUNTIFS(Students!$O:$O,"Declined",Students!$F:$F,$A15) -> 8 | C15: =COUNTIFS(Students!$O:$O,"EL",Students!$G:$G,$A15)+COUNTIFS(Students!$O:$O,"Declined",Students!$G:$G,$A15) -> 6 | D15: =COUNTIFS(Students!$O:$O,"EL",Students!$H:$H,$A15)+COUNTIFS(Students!$O:$O,"Declined",Students!$H:$H,$A15) -> 6 | E15: =COUNTIFS(Students!$O:$O,"EL",Students!$I:$I,$A15)+COUNTIFS(Students!$O:$O,"Declined",Students!$I:$I,$A15) -> 5 | H15: Average growth (levels) | I15: =IFERROR(ROUND((SUMIFS(Students!$N:$N,Students!$O:$O,"EL")+SUMIFS(Students!$N:$N,Students!$O:$O,"Declined"))/I14,2),0) -> 0.4
A16: 3 | B16: =COUNTIFS(Students!$O:$O,"EL",Students!$F:$F,$A16)+COUNTIFS(Students!$O:$O,"Declined",Students!$F:$F,$A16) -> 6 | C16: =COUNTIFS(Students!$O:$O,"EL",Students!$G:$G,$A16)+COUNTIFS(Students!$O:$O,"Declined",Students!$G:$G,$A16) -> 5 | D16: =COUNTIFS(Students!$O:$O,"EL",Students!$H:$H,$A16)+COUNTIFS(Students!$O:$O,"Declined",Students!$H:$H,$A16) -> 6 | E16: =COUNTIFS(Students!$O:$O,"EL",Students!$I:$I,$A16)+COUNTIFS(Students!$O:$O,"Declined",Students!$I:$I,$A16) -> 4 | H16: Grew ≥ ½ level | I16: =COUNTIFS(Students!$O:$O,"EL",Students!$N:$N,">=0.5")+COUNTIFS(Students!$O:$O,"Declined",Students!$N:$N,">=0.5") -> 21
A17: 4 | B17: =COUNTIFS(Students!$O:$O,"EL",Students!$F:$F,$A17)+COUNTIFS(Students!$O:$O,"Declined",Students!$F:$F,$A17) -> 6 | C17: =COUNTIFS(Students!$O:$O,"EL",Students!$G:$G,$A17)+COUNTIFS(Students!$O:$O,"Declined",Students!$G:$G,$A17) -> 7 | D17: =COUNTIFS(Students!$O:$O,"EL",Students!$H:$H,$A17)+COUNTIFS(Students!$O:$O,"Declined",Students!$H:$H,$A17) -> 10 | E17: =COUNTIFS(Students!$O:$O,"EL",Students!$I:$I,$A17)+COUNTIFS(Students!$O:$O,"Declined",Students!$I:$I,$A17) -> 8 | H17: No growth or declined | I17: =COUNTIFS(Students!$O:$O,"EL",Students!$N:$N,"<=0")+COUNTIFS(Students!$O:$O,"Declined",Students!$N:$N,"<=0") -> 8
A18: 5 | B18: =COUNTIFS(Students!$O:$O,"EL",Students!$F:$F,$A18)+COUNTIFS(Students!$O:$O,"Declined",Students!$F:$F,$A18) -> 12 | C18: =COUNTIFS(Students!$O:$O,"EL",Students!$G:$G,$A18)+COUNTIFS(Students!$O:$O,"Declined",Students!$G:$G,$A18) -> 8 | D18: =COUNTIFS(Students!$O:$O,"EL",Students!$H:$H,$A18)+COUNTIFS(Students!$O:$O,"Declined",Students!$H:$H,$A18) -> 2 | E18: =COUNTIFS(Students!$O:$O,"EL",Students!$I:$I,$A18)+COUNTIFS(Students!$O:$O,"Declined",Students!$I:$I,$A18) -> 7 | H18: % grew ≥ ½ level | I18: =IF(I14=0,0,I16/I14) -> 0.7
A21: 5 · Years in program (active ELs) | E21: 6 · Lowest domain (where LSPs should focus)
A22: Years | B22: Students | C22: Proficient this year | E22: Domain | F22: Students
A23: 1 | B23: =COUNTIFS(Students!$O:$O,"EL",Students!$E:$E,"1")+COUNTIFS(Students!$O:$O,"Declined",Students!$E:$E,"1") -> 6 | C23: =COUNTIFS(Students!$O:$O,"EL",Students!$E:$E,"1",Students!$K:$K,"Yes")+COUNTIFS(Students!$O:$O,"Declined",Students!$E:$E,"1",Students!$K:$K,"Yes") -> 0 | E23: Listening | F23: =COUNTIFS(Students!$O:$O,"EL",Students!$L:$L,E23)+COUNTIFS(Students!$O:$O,"Declined",Students!$L:$L,E23) -> 5
A24: 2 | B24: =COUNTIFS(Students!$O:$O,"EL",Students!$E:$E,"2")+COUNTIFS(Students!$O:$O,"Declined",Students!$E:$E,"2") -> 9 | C24: =COUNTIFS(Students!$O:$O,"EL",Students!$E:$E,"2",Students!$K:$K,"Yes")+COUNTIFS(Students!$O:$O,"Declined",Students!$E:$E,"2",Students!$K:$K,"Yes") -> 0 | E24: Speaking | F24: =COUNTIFS(Students!$O:$O,"EL",Students!$L:$L,E24)+COUNTIFS(Students!$O:$O,"Declined",Students!$L:$L,E24) -> 12
A25: 3 | B25: =COUNTIFS(Students!$O:$O,"EL",Students!$E:$E,"3")+COUNTIFS(Students!$O:$O,"Declined",Students!$E:$E,"3") -> 5 | C25: =COUNTIFS(Students!$O:$O,"EL",Students!$E:$E,"3",Students!$K:$K,"Yes")+COUNTIFS(Students!$O:$O,"Declined",Students!$E:$E,"3",Students!$K:$K,"Yes") -> 0 | E25: Reading | F25: =COUNTIFS(Students!$O:$O,"EL",Students!$L:$L,E25)+COUNTIFS(Students!$O:$O,"Declined",Students!$L:$L,E25) -> 18
A26: 4 | B26: =COUNTIFS(Students!$O:$O,"EL",Students!$E:$E,"4")+COUNTIFS(Students!$O:$O,"Declined",Students!$E:$E,"4") -> 5 | C26: =COUNTIFS(Students!$O:$O,"EL",Students!$E:$E,"4",Students!$K:$K,"Yes")+COUNTIFS(Students!$O:$O,"Declined",Students!$E:$E,"4",Students!$K:$K,"Yes") -> 1 | E26: Writing | F26: =COUNTIFS(Students!$O:$O,"EL",Students!$L:$L,E26)+COUNTIFS(Students!$O:$O,"Declined",Students!$L:$L,E26) -> 1
A27: 5+ | B27: =COUNTIFS(Students!$O:$O,"EL",Students!$E:$E,">=5")+COUNTIFS(Students!$O:$O,"Declined",Students!$E:$E,">=5") -> 11 | C27: =COUNTIFS(Students!$O:$O,"EL",Students!$E:$E,">=5",Students!$K:$K,"Yes")+COUNTIFS(Students!$O:$O,"Declined",Students!$E:$E,">=5",Students!$K:$K,"Yes") -> 10
A29: Long-term ELs (6+ yrs) are a §15 / OCR flag — see Students sheet filter Years ≥ 6.
A31: 7 · By grade (active ELs) | H31: 8 · Home languages (top 8, type them in blue)
A32: Grade | B32: ELs | C32: Proficient | D32: % proficient | E32: Avg years | F32: IEP | H32: Language | I32: ELs
A33: K | B33: =COUNTIFS(Students!$O:$O,"EL",Students!$C:$C,$A33)+COUNTIFS(Students!$O:$O,"Declined",Students!$C:$C,$A33) -> 5 | C33: =COUNTIFS(Students!$O:$O,"EL",Students!$C:$C,$A33,Students!$K:$K,"Yes")+COUNTIFS(Students!$O:$O,"Declined",Students!$C:$C,$A33,Students!$K:$K,"Yes") -> 3 | D33: =IF(B33=0,0,C33/B33) -> 0.6 | E33: =IFERROR(ROUND((SUMIFS(Students!$E:$E,Students!$O:$O,"EL",Students!$C:$C,$A33)+SUMIFS(Students!$E:$E,Students!$O:$O,"Declined",Students!$C:$C,$A33))/B33,1),0) -> 3.8 | F33: =COUNTIFS(Students!$O:$O,"EL",Students!$C:$C,$A33,Students!$P:$P,"Y")+COUNTIFS(Students!$O:$O,"Declined",Students!$C:$C,$A33,Students!$P:$P,"Y") -> 2 | H33: Spanish | I33: =IF(H33="","",COUNTIFS(Students!$O:$O,"EL",Students!$D:$D,H33)+COUNTIFS(Students!$O:$O,"Declined",Students!$D:$D,H33)) -> 25
A34: 1 | B34: =COUNTIFS(Students!$O:$O,"EL",Students!$C:$C,$A34)+COUNTIFS(Students!$O:$O,"Declined",Students!$C:$C,$A34) -> 2 | C34: =COUNTIFS(Students!$O:$O,"EL",Students!$C:$C,$A34,Students!$K:$K,"Yes")+COUNTIFS(Students!$O:$O,"Declined",Students!$C:$C,$A34,Students!$K:$K,"Yes") -> 0 | D34: =IF(B34=0,0,C34/B34) -> 0 | E34: =IFERROR(ROUND((SUMIFS(Students!$E:$E,Students!$O:$O,"EL",Students!$C:$C,$A34)+SUMIFS(Students!$E:$E,Students!$O:$O,"Declined",Students!$C:$C,$A34))/B34,1),0) -> 3.5 | F34: =COUNTIFS(Students!$O:$O,"EL",Students!$C:$C,$A34,Students!$P:$P,"Y")+COUNTIFS(Students!$O:$O,"Declined",Students!$C:$C,$A34,Students!$P:$P,"Y") -> 0 | H34: Vietnamese | I34: =IF(H34="","",COUNTIFS(Students!$O:$O,"EL",Students!$D:$D,H34)+COUNTIFS(Students!$O:$O,"Declined",Students!$D:$D,H34)) -> 1
A35: 2 | B35: =COUNTIFS(Students!$O:$O,"EL",Students!$C:$C,$A35)+COUNTIFS(Students!$O:$O,"Declined",Students!$C:$C,$A35) -> 1 | C35: =COUNTIFS(Students!$O:$O,"EL",Students!$C:$C,$A35,Students!$K:$K,"Yes")+COUNTIFS(Students!$O:$O,"Declined",Students!$C:$C,$A35,Students!$K:$K,"Yes") -> 0 | D35: =IF(B35=0,0,C35/B35) -> 0 | E35: =IFERROR(ROUND((SUMIFS(Students!$E:$E,Students!$O:$O,"EL",Students!$C:$C,$A35)+SUMIFS(Students!$E:$E,Students!$O:$O,"Declined",Students!$C:$C,$A35))/B35,1),0) -> 2 | F35: =COUNTIFS(Students!$O:$O,"EL",Students!$C:$C,$A35,Students!$P:$P,"Y")+COUNTIFS(Students!$O:$O,"Declined",Students!$C:$C,$A35,Students!$P:$P,"Y") -> 0 | H35: Arabic | I35: =IF(H35="","",COUNTIFS(Students!$O:$O,"EL",Students!$D:$D,H35)+COUNTIFS(Students!$O:$O,"Declined",Students!$D:$D,H35)) -> 3
A36: 3 | B36: =COUNTIFS(Students!$O:$O,"EL",Students!$C:$C,$A36)+COUNTIFS(Students!$O:$O,"Declined",Students!$C:$C,$A36) -> 1 | C36: =COUNTIFS(Students!$O:$O,"EL",Students!$C:$C,$A36,Students!$K:$K,"Yes")+COUNTIFS(Students!$O:$O,"Declined",Students!$C:$C,$A36,Students!$K:$K,"Yes") -> 0 | D36: =IF(B36=0,0,C36/B36) -> 0 | E36: =IFERROR(ROUND((SUMIFS(Students!$E:$E,Students!$O:$O,"EL",Students!$C:$C,$A36)+SUMIFS(Students!$E:$E,Students!$O:$O,"Declined",Students!$C:$C,$A36))/B36,1),0) -> 3 | F36: =COUNTIFS(Students!$O:$O,"EL",Students!$C:$C,$A36,Students!$P:$P,"Y")+COUNTIFS(Students!$O:$O,"Declined",Students!$C:$C,$A36,Students!$P:$P,"Y") -> 0 | H36: Haitian Creole | I36: =IF(H36="","",COUNTIFS(Students!$O:$O,"EL",Students!$D:$D,H36)+COUNTIFS(Students!$O:$O,"Declined",Students!$D:$D,H36)) -> 3
A37: 4 | B37: =COUNTIFS(Students!$O:$O,"EL",Students!$C:$C,$A37)+COUNTIFS(Students!$O:$O,"Declined",Students!$C:$C,$A37) -> 1 | C37: =COUNTIFS(Students!$O:$O,"EL",Students!$C:$C,$A37,Students!$K:$K,"Yes")+COUNTIFS(Students!$O:$O,"Declined",Students!$C:$C,$A37,Students!$K:$K,"Yes") -> 0 | D37: =IF(B37=0,0,C37/B37) -> 0 | E37: =IFERROR(ROUND((SUMIFS(Students!$E:$E,Students!$O:$O,"EL",Students!$C:$C,$A37)+SUMIFS(Students!$E:$E,Students!$O:$O,"Declined",Students!$C:$C,$A37))/B37,1),0) -> 1 | F37: =COUNTIFS(Students!$O:$O,"EL",Students!$C:$C,$A37,Students!$P:$P,"Y")+COUNTIFS(Students!$O:$O,"Declined",Students!$C:$C,$A37,Students!$P:$P,"Y") -> 0 | H37: Chinese | I37: =IF(H37="","",COUNTIFS(Students!$O:$O,"EL",Students!$D:$D,H37)+COUNTIFS(Students!$O:$O,"Declined",Students!$D:$D,H37)) -> 1
A38: 5 | B38: =COUNTIFS(Students!$O:$O,"EL",Students!$C:$C,$A38)+COUNTIFS(Students!$O:$O,"Declined",Students!$C:$C,$A38) -> 3 | C38: =COUNTIFS(Students!$O:$O,"EL",Students!$C:$C,$A38,Students!$K:$K,"Yes")+COUNTIFS(Students!$O:$O,"Declined",Students!$C:$C,$A38,Students!$K:$K,"Yes") -> 1 | D38: =IF(B38=0,0,C38/B38) -> 0.33333333 | E38: =IFERROR(ROUND((SUMIFS(Students!$E:$E,Students!$O:$O,"EL",Students!$C:$C,$A38)+SUMIFS(Students!$E:$E,Students!$O:$O,"Declined",Students!$C:$C,$A38))/B38,1),0) -> 3 | F38: =COUNTIFS(Students!$O:$O,"EL",Students!$C:$C,$A38,Students!$P:$P,"Y")+COUNTIFS(Students!$O:$O,"Declined",Students!$C:$C,$A38,Students!$P:$P,"Y") -> 0 | H38: K'iche' | I38: =IF(H38="","",COUNTIFS(Students!$O:$O,"EL",Students!$D:$D,H38)+COUNTIFS(Students!$O:$O,"Declined",Students!$D:$D,H38)) -> 1
A39: 6 | B39: =COUNTIFS(Students!$O:$O,"EL",Students!$C:$C,$A39)+COUNTIFS(Students!$O:$O,"Declined",Students!$C:$C,$A39) -> 4 | C39: =COUNTIFS(Students!$O:$O,"EL",Students!$C:$C,$A39,Students!$K:$K,"Yes")+COUNTIFS(Students!$O:$O,"Declined",Students!$C:$C,$A39,Students!$K:$K,"Yes") -> 1 | D39: =IF(B39=0,0,C39/B39) -> 0.25 | E39: =IFERROR(ROUND((SUMIFS(Students!$E:$E,Students!$O:$O,"EL",Students!$C:$C,$A39)+SUMIFS(Students!$E:$E,Students!$O:$O,"Declined",Students!$C:$C,$A39))/B39,1),0) -> 3 | F39: =COUNTIFS(Students!$O:$O,"EL",Students!$C:$C,$A39,Students!$P:$P,"Y")+COUNTIFS(Students!$O:$O,"Declined",Students!$C:$C,$A39,Students!$P:$P,"Y") -> 0 | H39: Portuguese | I39: =IF(H39="","",COUNTIFS(Students!$O:$O,"EL",Students!$D:$D,H39)+COUNTIFS(Students!$O:$O,"Declined",Students!$D:$D,H39)) -> 2
A40: 7 | B40: =COUNTIFS(Students!$O:$O,"EL",Students!$C:$C,$A40)+COUNTIFS(Students!$O:$O,"Declined",Students!$C:$C,$A40) -> 4 | C40: =COUNTIFS(Students!$O:$O,"EL",Students!$C:$C,$A40,Students!$K:$K,"Yes")+COUNTIFS(Students!$O:$O,"Declined",Students!$C:$C,$A40,Students!$K:$K,"Yes") -> 2 | D40: =IF(B40=0,0,C40/B40) -> 0.5 | E40: =IFERROR(ROUND((SUMIFS(Students!$E:$E,Students!$O:$O,"EL",Students!$C:$C,$A40)+SUMIFS(Students!$E:$E,Students!$O:$O,"Declined",Students!$C:$C,$A40))/B40,1),0) -> 4.3 | F40: =COUNTIFS(Students!$O:$O,"EL",Students!$C:$C,$A40,Students!$P:$P,"Y")+COUNTIFS(Students!$O:$O,"Declined",Students!$C:$C,$A40,Students!$P:$P,"Y") -> 1 | I40: =IF(H40="","",COUNTIFS(Students!$O:$O,"EL",Students!$D:$D,H40)+COUNTIFS(Students!$O:$O,"Declined",Students!$D:$D,H40))
A41: 8 | B41: =COUNTIFS(Students!$O:$O,"EL",Students!$C:$C,$A41)+COUNTIFS(Students!$O:$O,"Declined",Students!$C:$C,$A41) -> 1 | C41: =COUNTIFS(Students!$O:$O,"EL",Students!$C:$C,$A41,Students!$K:$K,"Yes")+COUNTIFS(Students!$O:$O,"Declined",Students!$C:$C,$A41,Students!$K:$K,"Yes") -> 0 | D41: =IF(B41=0,0,C41/B41) -> 0 | E41: =IFERROR(ROUND((SUMIFS(Students!$E:$E,Students!$O:$O,"EL",Students!$C:$C,$A41)+SUMIFS(Students!$E:$E,Students!$O:$O,"Declined",Students!$C:$C,$A41))/B41,1),0) -> 2 | F41: =COUNTIFS(Students!$O:$O,"EL",Students!$C:$C,$A41,Students!$P:$P,"Y")+COUNTIFS(Students!$O:$O,"Declined",Students!$C:$C,$A41,Students!$P:$P,"Y") -> 1
A42: 9 | B42: =COUNTIFS(Students!$O:$O,"EL",Students!$C:$C,$A42)+COUNTIFS(Students!$O:$O,"Declined",Students!$C:$C,$A42) -> 5 | C42: =COUNTIFS(Students!$O:$O,"EL",Students!$C:$C,$A42,Students!$K:$K,"Yes")+COUNTIFS(Students!$O:$O,"Declined",Students!$C:$C,$A42,Students!$K:$K,"Yes") -> 2 | D42: =IF(B42=0,0,C42/B42) -> 0.4 | E42: =IFERROR(ROUND((SUMIFS(Students!$E:$E,Students!$O:$O,"EL",Students!$C:$C,$A42)+SUMIFS(Students!$E:$E,Students!$O:$O,"Declined",Students!$C:$C,$A42))/B42,1),0) -> 4 | F42: =COUNTIFS(Students!$O:$O,"EL",Students!$C:$C,$A42,Students!$P:$P,"Y")+COUNTIFS(Students!$O:$O,"Declined",Students!$C:$C,$A42,Students!$P:$P,"Y") -> 0
A43: 10 | B43: =COUNTIFS(Students!$O:$O,"EL",Students!$C:$C,$A43)+COUNTIFS(Students!$O:$O,"Declined",Students!$C:$C,$A43) -> 5 | C43: =COUNTIFS(Students!$O:$O,"EL",Students!$C:$C,$A43,Students!$K:$K,"Yes")+COUNTIFS(Students!$O:$O,"Declined",Students!$C:$C,$A43,Students!$K:$K,"Yes") -> 2 | D43: =IF(B43=0,0,C43/B43) -> 0.4 | E43: =IFERROR(ROUND((SUMIFS(Students!$E:$E,Students!$O:$O,"EL",Students!$C:$C,$A43)+SUMIFS(Students!$E:$E,Students!$O:$O,"Declined",Students!$C:$C,$A43))/B43,1),0) -> 3.6 | F43: =COUNTIFS(Students!$O:$O,"EL",Students!$C:$C,$A43,Students!$P:$P,"Y")+COUNTIFS(Students!$O:$O,"Declined",Students!$C:$C,$A43,Students!$P:$P,"Y") -> 0
A44: 11 | B44: =COUNTIFS(Students!$O:$O,"EL",Students!$C:$C,$A44)+COUNTIFS(Students!$O:$O,"Declined",Students!$C:$C,$A44) -> 2 | C44: =COUNTIFS(Students!$O:$O,"EL",Students!$C:$C,$A44,Students!$K:$K,"Yes")+COUNTIFS(Students!$O:$O,"Declined",Students!$C:$C,$A44,Students!$K:$K,"Yes") -> 0 | D44: =IF(B44=0,0,C44/B44) -> 0 | E44: =IFERROR(ROUND((SUMIFS(Students!$E:$E,Students!$O:$O,"EL",Students!$C:$C,$A44)+SUMIFS(Students!$E:$E,Students!$O:$O,"Declined",Students!$C:$C,$A44))/B44,1),0) -> 1.5 | F44: =COUNTIFS(Students!$O:$O,"EL",Students!$C:$C,$A44,Students!$P:$P,"Y")+COUNTIFS(Students!$O:$O,"Declined",Students!$C:$C,$A44,Students!$P:$P,"Y") -> 0
A45: 12 | B45: =COUNTIFS(Students!$O:$O,"EL",Students!$C:$C,$A45)+COUNTIFS(Students!$O:$O,"Declined",Students!$C:$C,$A45) -> 2 | C45: =COUNTIFS(Students!$O:$O,"EL",Students!$C:$C,$A45,Students!$K:$K,"Yes")+COUNTIFS(Students!$O:$O,"Declined",Students!$C:$C,$A45,Students!$K:$K,"Yes") -> 0 | D45: =IF(B45=0,0,C45/B45) -> 0 | E45: =IFERROR(ROUND((SUMIFS(Students!$E:$E,Students!$O:$O,"EL",Students!$C:$C,$A45)+SUMIFS(Students!$E:$E,Students!$O:$O,"Declined",Students!$C:$C,$A45))/B45,1),0) -> 3 | F45: =COUNTIFS(Students!$O:$O,"EL",Students!$C:$C,$A45,Students!$P:$P,"Y")+COUNTIFS(Students!$O:$O,"Declined",Students!$C:$C,$A45,Students!$P:$P,"Y") -> 0
A46: Total | B46: =SUM(B33:B45) -> 36 | C46: =SUM(C33:C45) -> 11 | D46: =IF(B46=0,0,C46/B46) -> 0.30555556 | E46: =IFERROR(ROUND((SUMIFS(Students!$E:$E,Students!$O:$O,"EL")+SUMIFS(Students!$E:$E,Students!$O:$O,"Declined"))/B46,1),0) -> 3.3 | F46: =SUM(F33:F45) -> 4

Sheet Students
A1: ID | B1: School | C1: Grade | D1: Home language | E1: Years in program | F1: Listening | G1: Speaking | H1: Reading | I1: Writing | J1: Overall (formula) | K1: Proficient? (formula) | L1: Lowest domain (formula) | M1: Last year overall | N1: Growth (formula) | O1: Status | P1: IEP | Q1: Notes
A2: S1001 | B2: Oak Park ES | C2: 5 | D2: Spanish | E2: 3 | F2: 3 | G2: 3 | H2: 2 | I2: 2 | J2: =IF(F2="","",IF(AND(F2>=4,G2>=4,H2>=4,I2>=4),"Proficient",IF(AND(F2<=2,G2<=2,H2<=2,I2<=2),"Emerging","Progressing"))) -> Progressing | K2: =IF(F2="","",IF(J2="Proficient","Yes","No")) -> No | L2: =IF(F2="","",INDEX({"Listening","Speaking","Reading","Writing"},MATCH(MIN(F2:I2),F2:I2,0))) -> Reading | M2: 2 | N2: =IF(OR(F2="",M2=""),"",ROUND(AVERAGE(F2:I2)-M2,1)) -> 0.5 | O2: EL | P2: N
A3: S1002 | B3: Laurel MS | C3: 8 | D3: Spanish | E3: 2 | F3: 1 | G3: 1 | H3: 1 | I3: 1 | J3: =IF(F3="","",IF(AND(F3>=4,G3>=4,H3>=4,I3>=4),"Proficient",IF(AND(F3<=2,G3<=2,H3<=2,I3<=2),"Emerging","Progressing"))) -> Emerging | K3: =IF(F3="","",IF(J3="Proficient","Yes","No")) -> No | L3: =IF(F3="","",INDEX({"Listening","Speaking","Reading","Writing"},MATCH(MIN(F3:I3),F3:I3,0))) -> Listening | M3: 1 | N3: =IF(OR(F3="",M3=""),"",ROUND(AVERAGE(F3:I3)-M3,1)) -> 0 | O3: EL | P3: Y
A4: S1003 | B4: Laurel MS | C4: 9 | D4: Spanish | E4: 1 | F4: 2 | G4: 1 | H4: 1 | I4: 1 | J4: =IF(F4="","",IF(AND(F4>=4,G4>=4,H4>=4,I4>=4),"Proficient",IF(AND(F4<=2,G4<=2,H4<=2,I4<=2),"Emerging","Progressing"))) -> Emerging | K4: =IF(F4="","",IF(J4="Proficient","Yes","No")) -> No | L4: =IF(F4="","",INDEX({"Listening","Speaking","Reading","Writing"},MATCH(MIN(F4:I4),F4:I4,0))) -> Speaking | N4: =IF(OR(F4="",M4=""),"",ROUND(AVERAGE(F4:I4)-M4,1)) | O4: Monitored Y1 | P4: N
A5: S1004 | B5: Oak Park ES | C5: 4 | D5: Spanish | E5: 1 | F5: 1 | G5: 1 | H5: 1 | I5: 1 | J5: =IF(F5="","",IF(AND(F5>=4,G5>=4,H5>=4,I5>=4),"Proficient",IF(AND(F5<=2,G5<=2,H5<=2,I5<=2),"Emerging","Progressing"))) -> Emerging | K5: =IF(F5="","",IF(J5="Proficient","Yes","No")) -> No | L5: =IF(F5="","",INDEX({"Listening","Speaking","Reading","Writing"},MATCH(MIN(F5:I5),F5:I5,0))) -> Listening | N5: =IF(OR(F5="",M5=""),"",ROUND(AVERAGE(F5:I5)-M5,1)) | O5: Monitored Y1 | P5: N
A6: S1005 | B6: Laurel HS | C6: 9 | D6: Arabic | E6: 2 | F6: 2 | G6: 2 | H6: 2 | I6: 1 | J6: =IF(F6="","",IF(AND(F6>=4,G6>=4,H6>=4,I6>=4),"Proficient",IF(AND(F6<=2,G6<=2,H6<=2,I6<=2),"Emerging","Progressing"))) -> Emerging | K6: =IF(F6="","",IF(J6="Proficient","Yes","No")) -> No | L6: =IF(F6="","",INDEX({"Listening","Speaking","Reading","Writing"},MATCH(MIN(F6:I6),F6:I6,0))) -> Writing | M6: 1 | N6: =IF(OR(F6="",M6=""),"",ROUND(AVERAGE(F6:I6)-M6,1)) -> 0.8 | O6: EL | P6: N
A7: S1006 | B7: Laurel HS | C7: 10 | D7: Spanish | E7: 4 | F7: 4 | G7: 4 | H7: 3 | I7: 4 | J7: =IF(F7="","",IF(AND(F7>=4,G7>=4,H7>=4,I7>=4),"Proficient",IF(AND(F7<=2,G7<=2,H7<=2,I7<=2),"Emerging","Progressing"))) -> Progressing | K7: =IF(F7="","",IF(J7="Proficient","Yes","No")) -> No | L7: =IF(F7="","",INDEX({"Listening","Speaking","Reading","Writing"},MATCH(MIN(F7:I7),F7:I7,0))) -> Reading | M7: 3 | N7: =IF(OR(F7="",M7=""),"",ROUND(AVERAGE(F7:I7)-M7,1)) -> 0.8 | O7: EL | P7: N
A8: S1007 | B8: Oak Park ES | C8: 1 | D8: Spanish | E8: 3 | F8: 4 | G8: 4 | H8: 3 | I8: 4 | J8: =IF(F8="","",IF(AND(F8>=4,G8>=4,H8>=4,I8>=4),"Proficient",IF(AND(F8<=2,G8<=2,H8<=2,I8<=2),"Emerging","Progressing"))) -> Progressing | K8: =IF(F8="","",IF(J8="Proficient","Yes","No")) -> No | L8: =IF(F8="","",INDEX({"Listening","Speaking","Reading","Writing"},MATCH(MIN(F8:I8),F8:I8,0))) -> Reading | M8: 3 | N8: =IF(OR(F8="",M8=""),"",ROUND(AVERAGE(F8:I8)-M8,1)) -> 0.8 | O8: EL | P8: N
A9: S1008 | B9: Laurel MS | C9: 10 | D9: Spanish | E9: 3 | F9: 3 | G9: 3 | H9: 2 | I9: 2 | J9: =IF(F9="","",IF(AND(F9>=4,G9>=4,H9>=4,I9>=4),"Proficient",IF(AND(F9<=2,G9<=2,H9<=2,I9<=2),"Emerging","Progressing"))) -> Progressing | K9: =IF(F9="","",IF(J9="Proficient","Yes","No")) -> No | L9: =IF(F9="","",INDEX({"Listening","Speaking","Reading","Writing"},MATCH(MIN(F9:I9),F9:I9,0))) -> Reading | M9: 2 | N9: =IF(OR(F9="",M9=""),"",ROUND(AVERAGE(F9:I9)-M9,1)) -> 0.5 | O9: Monitored Y1 | P9: N
A10: S1009 | B10: Oak Park ES | C10: K | D10: Spanish | E10: 5 | F10: 5 | G10: 4 | H10: 4 | I10: 5 | J10: =IF(F10="","",IF(AND(F10>=4,G10>=4,H10>=4,I10>=4),"Proficient",IF(AND(F10<=2,G10<=2,H10<=2,I10<=2),"Emerging","Progressing"))) -> Proficient | K10: =IF(F10="","",IF(J10="Proficient","Yes","No")) -> Yes | L10: =IF(F10="","",INDEX({"Listening","Speaking","Reading","Writing"},MATCH(MIN(F10:I10),F10:I10,0))) -> Speaking | M10: 4 | N10: =IF(OR(F10="",M10=""),"",ROUND(AVERAGE(F10:I10)-M10,1)) -> 0.5 | O10: EL | P10: Y
A11: S1010 | B11: Laurel HS | C11: 5 | D11: Portuguese | E11: 5 | F11: 5 | G11: 5 | H11: 5 | I11: 5 | J11: =IF(F11="","",IF(AND(F11>=4,G11>=4,H11>=4,I11>=4),"Proficient",IF(AND(F11<=2,G11<=2,H11<=2,I11<=2),"Emerging","Progressing"))) -> Proficient | K11: =IF(F11="","",IF(J11="Proficient","Yes","No")) -> Yes | L11: =IF(F11="","",INDEX({"Listening","Speaking","Reading","Writing"},MATCH(MIN(F11:I11),F11:I11,0))) -> Listening | M11: 5 | N11: =IF(OR(F11="",M11=""),"",ROUND(AVERAGE(F11:I11)-M11,1)) -> 0 | O11: EL | P11: N
A12: S1011 | B12: Laurel MS | C12: 12 | D12: Spanish | E12: 5 | F12: 4 | G12: 4 | H12: 3 | I12: 3 | J12: =IF(F12="","",IF(AND(F12>=4,G12>=4,H12>=4,I12>=4),"Proficient",IF(AND(F12<=2,G12<=2,H12<=2,I12<=2),"Emerging","Progressing"))) -> Progressing | K12: =IF(F12="","",IF(J12="Proficient","Yes","No")) -> No | L12: =IF(F12="","",INDEX({"Listening","Speaking","Reading","Writing"},MATCH(MIN(F12:I12),F12:I12,0))) -> Reading | M12: 3 | N12: =IF(OR(F12="",M12=""),"",ROUND(AVERAGE(F12:I12)-M12,1)) -> 0.5 | O12: EL | P12: N
A13: S1012 | B13: Laurel MS | C13: 10 | D13: Spanish | E13: 5 | F13: 5 | G13: 5 | H13: 4 | I13: 5 | J13: =IF(F13="","",IF(AND(F13>=4,G13>=4,H13>=4,I13>=4),"Proficient",IF(AND(F13<=2,G13<=2,H13<=2,I13<=2),"Emerging","Progressing"))) -> Proficient | K13: =IF(F13="","",IF(J13="Proficient","Yes","No")) -> Yes | L13: =IF(F13="","",INDEX({"Listening","Speaking","Reading","Writing"},MATCH(MIN(F13:I13),F13:I13,0))) -> Reading | M13: 4 | N13: =IF(OR(F13="",M13=""),"",ROUND(AVERAGE(F13:I13)-M13,1)) -> 0.8 | O13: EL | P13: N
A14: S1013 | B14: Laurel MS | C14: K | D14: K'iche' | E14: 2 | F14: 2 | G14: 1 | H14: 1 | I14: 1 | J14: =IF(F14="","",IF(AND(F14>=4,G14>=4,H14>=4,I14>=4),"Proficient",IF(AND(F14<=2,G14<=2,H14<=2,I14<=2),"Emerging","Progressing"))) -> Emerging | K14: =IF(F14="","",IF(J14="Proficient","Yes","No")) -> No | L14: =IF(F14="","",INDEX({"Listening","Speaking","Reading","Writing"},MATCH(MIN(F14:I14),F14:I14,0))) -> Speaking | M14: 1 | N14: =IF(OR(F14="",M14=""),"",ROUND(AVERAGE(F14:I14)-M14,1)) -> 0.3 | O14: EL | P14: N
A15: S1014 | B15: Laurel HS | C15: 5 | D15: Haitian Creole | E15: 3 | F15: 3 | G15: 2 | H15: 2 | I15: 3 | J15: =IF(F15="","",IF(AND(F15>=4,G15>=4,H15>=4,I15>=4),"Proficient",IF(AND(F15<=2,G15<=2,H15<=2,I15<=2),"Emerging","Progressing"))) -> Progressing | K15: =IF(F15="","",IF(J15="Proficient","Yes","No")) -> No | L15: =IF(F15="","",INDEX({"Listening","Speaking","Reading","Writing"},MATCH(MIN(F15:I15),F15:I15,0))) -> Speaking | M15: 2 | N15: =IF(OR(F15="",M15=""),"",ROUND(AVERAGE(F15:I15)-M15,1)) -> 0.5 | O15: Monitored Y1 | P15: Y
A16: S1015 | B16: Laurel HS | C16: 6 | D16: Arabic | E16: 1 | F16: 3 | G16: 2 | H16: 1 | I16: 2 | J16: =IF(F16="","",IF(AND(F16>=4,G16>=4,H16>=4,I16>=4),"Proficient",IF(AND(F16<=2,G16<=2,H16<=2,I16<=2),"Emerging","Progressing"))) -> Progressing | K16: =IF(F16="","",IF(J16="Proficient","Yes","No")) -> No | L16: =IF(F16="","",INDEX({"Listening","Speaking","Reading","Writing"},MATCH(MIN(F16:I16),F16:I16,0))) -> Reading | N16: =IF(OR(F16="",M16=""),"",ROUND(AVERAGE(F16:I16)-M16,1)) | O16: EL | P16: N
A17: S1016 | B17: Oak Park ES | C17: 5 | D17: Spanish | E17: 1 | F17: 1 | G17: 1 | H17: 1 | I17: 1 | J17: =IF(F17="","",IF(AND(F17>=4,G17>=4,H17>=4,I17>=4),"Proficient",IF(AND(F17<=2,G17<=2,H17<=2,I17<=2),"Emerging","Progressing"))) -> Emerging | K17: =IF(F17="","",IF(J17="Proficient","Yes","No")) -> No | L17: =IF(F17="","",INDEX({"Listening","Speaking","Reading","Writing"},MATCH(MIN(F17:I17),F17:I17,0))) -> Listening | N17: =IF(OR(F17="",M17=""),"",ROUND(AVERAGE(F17:I17)-M17,1)) | O17: EL | P17: N
A18: S1017 | B18: Laurel HS | C18: 11 | D18: Portuguese | E18: 1 | F18: 2 | G18: 1 | H18: 1 | I18: 1 | J18: =IF(F18="","",IF(AND(F18>=4,G18>=4,H18>=4,I18>=4),"Proficient",IF(AND(F18<=2,G18<=2,H18<=2,I18<=2),"Emerging","Progressing"))) -> Emerging | K18: =IF(F18="","",IF(J18="Proficient","Yes","No")) -> No | L18: =IF(F18="","",INDEX({"Listening","Speaking","Reading","Writing"},MATCH(MIN(F18:I18),F18:I18,0))) -> Speaking | N18: =IF(OR(F18="",M18=""),"",ROUND(AVERAGE(F18:I18)-M18,1)) | O18: EL | P18: N
A19: S1018 | B19: Laurel MS | C19: 11 | D19: Vietnamese | E19: 2 | F19: 2 | G19: 2 | H19: 1 | I19: 2 | J19: =IF(F19="","",IF(AND(F19>=4,G19>=4,H19>=4,I19>=4),"Proficient",IF(AND(F19<=2,G19<=2,H19<=2,I19<=2),"Emerging","Progressing"))) -> Emerging | K19: =IF(F19="","",IF(J19="Proficient","Yes","No")) -> No | L19: =IF(F19="","",INDEX({"Listening","Speaking","Reading","Writing"},MATCH(MIN(F19:I19),F19:I19,0))) -> Reading | M19: 2 | N19: =IF(OR(F19="",M19=""),"",ROUND(AVERAGE(F19:I19)-M19,1)) -> -0.3 | O19: EL | P19: N
A20: S1019 | B20: Oak Park ES | C20: 7 | D20: Spanish | E20: 5 | F20: 5 | G20: 4 | H20: 4 | I20: 5 | J20: =IF(F20="","",IF(AND(F20>=4,G20>=4,H20>=4,I20>=4),"Proficient",IF(AND(F20<=2,G20<=2,H20<=2,I20<=2),"Emerging","Progressing"))) -> Proficient | K20: =IF(F20="","",IF(J20="Proficient","Yes","No")) -> Yes | L20: =IF(F20="","",INDEX({"Listening","Speaking","Reading","Writing"},MATCH(MIN(F20:I20),F20:I20,0))) -> Speaking | M20: 4 | N20: =IF(OR(F20="",M20=""),"",ROUND(AVERAGE(F20:I20)-M20,1)) -> 0.5 | O20: EL | P20: N
A21: S1020 | B21: Oak Park ES | C21: 4 | D21: Spanish | E21: 1 | F21: 2 | G21: 1 | H21: 1 | I21: 1 | J21: =IF(F21="","",IF(AND(F21>=4,G21>=4,H21>=4,I21>=4),"Proficient",IF(AND(F21<=2,G21<=2,H21<=2,I21<=2),"Emerging","Progressing"))) -> Emerging | K21: =IF(F21="","",IF(J21="Proficient","Yes","No")) -> No | L21: =IF(F21="","",INDEX({"Listening","Speaking","Reading","Writing"},MATCH(MIN(F21:I21),F21:I21,0))) -> Speaking | N21: =IF(OR(F21="",M21=""),"",ROUND(AVERAGE(F21:I21)-M21,1)) | O21: Declined | P21: N
A22: S1021 | B22: Laurel HS | C22: 9 | D22: Spanish | E22: 6 | F22: 5 | G22: 5 | H22: 4 | I22: 5 | J22: =IF(F22="","",IF(AND(F22>=4,G22>=4,H22>=4,I22>=4),"Proficient",IF(AND(F22<=2,G22<=2,H22<=2,I22<=2),"Emerging","Progressing"))) -> Proficient | K22: =IF(F22="","",IF(J22="Proficient","Yes","No")) -> Yes | L22: =IF(F22="","",INDEX({"Listening","Speaking","Reading","Writing"},MATCH(MIN(F22:I22),F22:I22,0))) -> Reading | M22: 4 | N22: =IF(OR(F22="",M22=""),"",ROUND(AVERAGE(F22:I22)-M22,1)) -> 0.8 | O22: EL | P22: N
A23: S1022 | B23: Laurel MS | C23: 7 | D23: Spanish | E23: 2 | F23: 3 | G23: 2 | H23: 1 | I23: 1 | J23: =IF(F23="","",IF(AND(F23>=4,G23>=4,H23>=4,I23>=4),"Proficient",IF(AND(F23<=2,G23<=2,H23<=2,I23<=2),"Emerging","Progressing"))) -> Progressing | K23: =IF(F23="","",IF(J23="Proficient","Yes","No")) -> No | L23: =IF(F23="","",INDEX({"Listening","Speaking","Reading","Writing"},MATCH(MIN(F23:I23),F23:I23,0))) -> Reading | M23: 2 | N23: =IF(OR(F23="",M23=""),"",ROUND(AVERAGE(F23:I23)-M23,1)) -> -0.3 | O23: EL | P23: Y
A24: S1023 | B24: Laurel MS | C24: 3 | D24: Spanish | E24: 3 | F24: 5 | G24: 4 | H24: 3 | I24: 3 | J24: =IF(F24="","",IF(AND(F24>=4,G24>=4,H24>=4,I24>=4),"Proficient",IF(AND(F24<=2,G24<=2,H24<=2,I24<=2),"Emerging","Progressing"))) -> Progressing | K24: =IF(F24="","",IF(J24="Proficient","Yes","No")) -> No | L24: =IF(F24="","",INDEX({"Listening","Speaking","Reading","Writing"},MATCH(MIN(F24:I24),F24:I24,0))) -> Reading | M24: 4 | N24: =IF(OR(F24="",M24=""),"",ROUND(AVERAGE(F24:I24)-M24,1)) -> -0.3 | O24: EL | P24: N
A25: S1024 | B25: Oak Park ES | C25: 10 | D25: Spanish | E25: 2 | F25: 4 | G25: 3 | H25: 2 | I25: 3 | J25: =IF(F25="","",IF(AND(F25>=4,G25>=4,H25>=4,I25>=4),"Proficient",IF(AND(F25<=2,G25<=2,H25<=2,I25<=2),"Emerging","Progressing"))) -> Progressing | K25: =IF(F25="","",IF(J25="Proficient","Yes","No")) -> No | L25: =IF(F25="","",INDEX({"Listening","Speaking","Reading","Writing"},MATCH(MIN(F25:I25),F25:I25,0))) -> Reading | M25: 2 | N25: =IF(OR(F25="",M25=""),"",ROUND(AVERAGE(F25:I25)-M25,1)) -> 1 | O25: EL | P25: N
A26: S1025 | B26: Laurel MS | C26: 7 | D26: Spanish | E26: 4 | F26: 4 | G26: 3 | H26: 3 | I26: 4 | J26: =IF(F26="","",IF(AND(F26>=4,G26>=4,H26>=4,I26>=4),"Proficient",IF(AND(F26<=2,G26<=2,H26<=2,I26<=2),"Emerging","Progressing"))) -> Progressing | K26: =IF(F26="","",IF(J26="Proficient","Yes","No")) -> No | L26: =IF(F26="","",INDEX({"Listening","Speaking","Reading","Writing"},MATCH(MIN(F26:I26),F26:I26,0))) -> Speaking | M26: 4 | N26: =IF(OR(F26="",M26=""),"",ROUND(AVERAGE(F26:I26)-M26,1)) -> -0.5 | O26: EL | P26: N
A27: S1026 | B27: Oak Park ES | C27: 9 | D27: Arabic | E27: 2 | F27: 2 | G27: 1 | H27: 2 | I27: 2 | J27: =IF(F27="","",IF(AND(F27>=4,G27>=4,H27>=4,I27>=4),"Proficient",IF(AND(F27<=2,G27<=2,H27<=2,I27<=2),"Emerging","Progressing"))) -> Emerging | K27: =IF(F27="","",IF(J27="Proficient","Yes","No")) -> No | L27: =IF(F27="","",INDEX({"Listening","Speaking","Reading","Writing"},MATCH(MIN(F27:I27),F27:I27,0))) -> Speaking | M27: 1 | N27: =IF(OR(F27="",M27=""),"",ROUND(AVERAGE(F27:I27)-M27,1)) -> 0.8 | O27: EL | P27: N
A28: S1027 | B28: Laurel HS | C28: 6 | D28: Spanish | E28: 2 | F28: 2 | G28: 1 | H28: 2 | I28: 1 | J28: =IF(F28="","",IF(AND(F28>=4,G28>=4,H28>=4,I28>=4),"Proficient",IF(AND(F28<=2,G28<=2,H28<=2,I28<=2),"Emerging","Progressing"))) -> Emerging | K28: =IF(F28="","",IF(J28="Proficient","Yes","No")) -> No | L28: =IF(F28="","",INDEX({"Listening","Speaking","Reading","Writing"},MATCH(MIN(F28:I28),F28:I28,0))) -> Speaking | M28: 1 | N28: =IF(OR(F28="",M28=""),"",ROUND(AVERAGE(F28:I28)-M28,1)) -> 0.5 | O28: EL | P28: N
A29: S1028 | B29: Laurel HS | C29: 6 | D29: Spanish | E29: 3 | F29: 3 | G29: 3 | H29: 2 | I29: 3 | J29: =IF(F29="","",IF(AND(F29>=4,G29>=4,H29>=4,I29>=4),"Proficient",IF(AND(F29<=2,G29<=2,H29<=2,I29<=2),"Emerging","Progressing"))) -> Progressing | K29: =IF(F29="","",IF(J29="Proficient","Yes","No")) -> No | L29: =IF(F29="","",INDEX({"Listening","Speaking","Reading","Writing"},MATCH(MIN(F29:I29),F29:I29,0))) -> Reading | M29: 2 | N29: =IF(OR(F29="",M29=""),"",ROUND(AVERAGE(F29:I29)-M29,1)) -> 0.8 | O29: Declined | P29: N
A30: S1029 | B30: Laurel MS | C30: K | D30: Spanish | E30: 5 | F30: 5 | G30: 4 | H30: 5 | I30: 4 | J30: =IF(F30="","",IF(AND(F30>=4,G30>=4,H30>=4,I30>=4),"Proficient",IF(AND(F30<=2,G30<=2,H30<=2,I30<=2),"Emerging","Progressing"))) -> Proficient | K30: =IF(F30="","",IF(J30="Proficient","Yes","No")) -> Yes | L30: =IF(F30="","",INDEX({"Listening","Speaking","Reading","Writing"},MATCH(MIN(F30:I30),F30:I30,0))) -> Speaking | M30: 4 | N30: =IF(OR(F30="",M30=""),"",ROUND(AVERAGE(F30:I30)-M30,1)) -> 0.5 | O30: Declined | P30: Y
A31: S1030 | B31: Laurel MS | C31: K | D31: Haitian Creole | E31: 1 | F31: 1 | G31: 1 | H31: 1 | I31: 1 | J31: =IF(F31="","",IF(AND(F31>=4,G31>=4,H31>=4,I31>=4),"Proficient",IF(AND(F31<=2,G31<=2,H31<=2,I31<=2),"Emerging","Progressing"))) -> Emerging | K31: =IF(F31="","",IF(J31="Proficient","Yes","No")) -> No | L31: =IF(F31="","",INDEX({"Listening","Speaking","Reading","Writing"},MATCH(MIN(F31:I31),F31:I31,0))) -> Listening | N31: =IF(OR(F31="",M31=""),"",ROUND(AVERAGE(F31:I31)-M31,1)) | O31: Declined | P31: N
A32: S1031 | B32: Laurel HS | C32: K | D32: Haitian Creole | E32: 6 | F32: 5 | G32: 5 | H32: 4 | I32: 4 | J32: =IF(F32="","",IF(AND(F32>=4,G32>=4,H32>=4,I32>=4),"Proficient",IF(AND(F32<=2,G32<=2,H32<=2,I32<=2),"Emerging","Progressing"))) -> Proficient | K32: =IF(F32="","",IF(J32="Proficient","Yes","No")) -> Yes | L32: =IF(F32="","",INDEX({"Listening","Speaking","Reading","Writing"},MATCH(MIN(F32:I32),F32:I32,0))) -> Reading | M32: 5 | N32: =IF(OR(F32="",M32=""),"",ROUND(AVERAGE(F32:I32)-M32,1)) -> -0.5 | O32: EL | P32: N
A33: S1032 | B33: Oak Park ES | C33: 7 | D33: Chinese | E33: 6 | F33: 5 | G33: 5 | H33: 4 | I33: 4 | J33: =IF(F33="","",IF(AND(F33>=4,G33>=4,H33>=4,I33>=4),"Proficient",IF(AND(F33<=2,G33<=2,H33<=2,I33<=2),"Emerging","Progressing"))) -> Proficient | K33: =IF(F33="","",IF(J33="Proficient","Yes","No")) -> Yes | L33: =IF(F33="","",INDEX({"Listening","Speaking","Reading","Writing"},MATCH(MIN(F33:I33),F33:I33,0))) -> Reading | M33: 4 | N33: =IF(OR(F33="",M33=""),"",ROUND(AVERAGE(F33:I33)-M33,1)) -> 0.5 | O33: EL | P33: N
A34: S1033 | B34: Laurel HS | C34: 6 | D34: Spanish | E34: 6 | F34: 5 | G34: 5 | H34: 4 | I34: 4 | J34: =IF(F34="","",IF(AND(F34>=4,G34>=4,H34>=4,I34>=4),"Proficient",IF(AND(F34<=2,G34<=2,H34<=2,I34<=2),"Emerging","Progressing"))) -> Proficient | K34: =IF(F34="","",IF(J34="Proficient","Yes","No")) -> Yes | L34: =IF(F34="","",INDEX({"Listening","Speaking","Reading","Writing"},MATCH(MIN(F34:I34),F34:I34,0))) -> Reading | M34: 4 | N34: =IF(OR(F34="",M34=""),"",ROUND(AVERAGE(F34:I34)-M34,1)) -> 0.5 | O34: EL | P34: N
A35: S1034 | B35: Laurel HS | C35: 10 | D35: Spanish | E35: 3 | F35: 3 | G35: 1 | H35: 1 | I35: 1 | J35: =IF(F35="","",IF(AND(F35>=4,G35>=4,H35>=4,I35>=4),"Proficient",IF(AND(F35<=2,G35<=2,H35<=2,I35<=2),"Emerging","Progressing"))) -> Progressing | K35: =IF(F35="","",IF(J35="Proficient","Yes","No")) -> No | L35: =IF(F35="","",INDEX({"Listening","Speaking","Reading","Writing"},MATCH(MIN(F35:I35),F35:I35,0))) -> Speaking | M35: 2 | N35: =IF(OR(F35="",M35=""),"",ROUND(AVERAGE(F35:I35)-M35,1)) -> -0.5 | O35: EL | P35: N
A36: S1035 | B36: Oak Park ES | C36: 2 | D36: Spanish | E36: 2 | F36: 2 | G36: 2 | H36: 1 | I36: 1 | J36: =IF(F36="","",IF(AND(F36>=4,G36>=4,H36>=4,I36>=4),"Proficient",IF(AND(F36<=2,G36<=2,H36<=2,I36<=2),"Emerging","Progressing"))) -> Emerging | K36: =IF(F36="","",IF(J36="Proficient","Yes","No")) -> No | L36: =IF(F36="","",INDEX({"Listening","Speaking","Reading","Writing"},MATCH(MIN(F36:I36),F36:I36,0))) -> Reading | M36: 1 | N36: =IF(OR(F36="",M36=""),"",ROUND(AVERAGE(F36:I36)-M36,1)) -> 0.5 | O36: EL | P36: N
A37: S1036 | B37: Laurel MS | C37: 10 | D37: Spanish | E37: 4 | F37: 5 | G37: 5 | H37: 4 | I37: 5 | J37: =IF(F37="","",IF(AND(F37>=4,G37>=4,H37>=4,I37>=4),"Proficient",IF(AND(F37<=2,G37<=2,H37<=2,I37<=2),"Emerging","Progressing"))) -> Proficient | K37: =IF(F37="","",IF(J37="Proficient","Yes","No")) -> Yes | L37: =IF(F37="","",INDEX({"Listening","Speaking","Reading","Writing"},MATCH(MIN(F37:I37),F37:I37,0))) -> Reading | M37: 4 | N37: =IF(OR(F37="",M37=""),"",ROUND(AVERAGE(F37:I37)-M37,1)) -> 0.8 | O37: EL | P37: N
A38: S1037 | B38: Laurel MS | C38: 9 | D38: Haitian Creole | E38: 6 | F38: 5 | G38: 5 | H38: 4 | I38: 5 | J38: =IF(F38="","",IF(AND(F38>=4,G38>=4,H38>=4,I38>=4),"Proficient",IF(AND(F38<=2,G38<=2,H38<=2,I38<=2),"Emerging","Progressing"))) -> Proficient | K38: =IF(F38="","",IF(J38="Proficient","Yes","No")) -> Yes | L38: =IF(F38="","",INDEX({"Listening","Speaking","Reading","Writing"},MATCH(MIN(F38:I38),F38:I38,0))) -> Reading | M38: 4 | N38: =IF(OR(F38="",M38=""),"",ROUND(AVERAGE(F38:I38)-M38,1)) -> 0.8 | O38: Declined | P38: N
A39: S1038 | B39: Laurel HS | C39: 12 | D39: Spanish | E39: 1 | F39: 1 | G39: 1 | H39: 1 | I39: 1 | J39: =IF(F39="","",IF(AND(F39>=4,G39>=4,H39>=4,I39>=4),"Proficient",IF(AND(F39<=2,G39<=2,H39<=2,I39<=2),"Emerging","Progressing"))) -> Emerging | K39: =IF(F39="","",IF(J39="Proficient","Yes","No")) -> No | L39: =IF(F39="","",INDEX({"Listening","Speaking","Reading","Writing"},MATCH(MIN(F39:I39),F39:I39,0))) -> Listening | N39: =IF(OR(F39="",M39=""),"",ROUND(AVERAGE(F39:I39)-M39,1)) | O39: EL | P39: N
A40: S1039 | B40: Laurel MS | C40: 1 | D40: Spanish | E40: 4 | F40: 4 | G40: 3 | H40: 4 | I40: 4 | J40: =IF(F40="","",IF(AND(F40>=4,G40>=4,H40>=4,I40>=4),"Proficient",IF(AND(F40<=2,G40<=2,H40<=2,I40<=2),"Emerging","Progressing"))) -> Progressing | K40: =IF(F40="","",IF(J40="Proficient","Yes","No")) -> No | L40: =IF(F40="","",INDEX({"Listening","Speaking","Reading","Writing"},MATCH(MIN(F40:I40),F40:I40,0))) -> Speaking | M40: 3 | N40: =IF(OR(F40="",M40=""),"",ROUND(AVERAGE(F40:I40)-M40,1)) -> 0.8 | O40: EL | P40: N
...
